Workbook

Sheet 1-Info Section Directions
A1: INFORMATION SECTION
A2: for the FSMC Cost Reimbursable RFP
A4: Insert School Sponsor Name in this cell
A5: Name of Sponsor
A6: Directions:
A7: The Sponsor representative will fill out each tab of the Information Section as applicable and include it in the contract bid packet. This will represent all information about cost, equipment, income, and service needs.
A8: The Bid Point Calculator and Evaluation Criteria Matrix is used to advise potential bidders of the value placed on non-price criteria items, which are used during the evaluation process. Non-price criteria items must be completed prior to submission to MDE for review.
A9: After bids are submitted by companies, the Bid Point Calculator and Evaluation Criteria Matrix is used to calculate which bidder will be awarded the contract. The bidder with the maximum number of points, not necessarily the lowest price, will be awarded the contract upon MDE review and approval.
A11: Tabs in light teal must be completed by the sponsor.
A12: Tabs in purple must be completed by the bidder.
A13: Both must complete areas of the bid sheet(s).

Sheet 2-Required Attachments
A1: REQUIRED ATTACHMENTS
A2: Sponsor must attach the following policies and procedures to this bid packet in PDF format: | D2: REQUIRED POLICIES AND PROCEDURES (FSMC contracts): As part of the draft packet of documents sent to MDE for pre-approval, all sponsors must include 1) procurement/purchasing policies AND procedures – must address the procedures sponsor staff must follow when procuring and purchasing goods and/or services, including requirements for micro-purchasing, formal and informal procurement, emergency purchasing, Buy American Provision, Geographic Preference, Minority and Women’s Businesses, etc.; 2) written code of conduct/conflict of interest policy - must specifically relate to the conduct of staff involved in purchasing goods and/or services (do not include a student’s code of conduct), must address a sponsor’s expectations for how staff should and should not conduct themselves during any procurement process, and must specify that there will not be any conflict of interest for anyone involved in the procurement or award processes; 3) small purchase thresholds – must specific the sponsor’s small purchase threshold dollar amount(s) and the procurement methods used by the sponsor based on purchase thresholds, and must be included in the bid packet even if the thresholds are the same as those required by state/federal guidance; 4) bid protest policy or procedure – must specify how bid protests are handled, including protest submission timelines, how and to whom protests should be submitted, etc. (keep in mind that the scope of the bid protest can only include the actual bid process, it doesn’t usually include the evaluation or scoring used in the award determination); 5) meal charge policy – outlines how a sponsor provides meals to students with insufficient funds and how debt is collected; and 6) bad debt policy – identifies a sponsor’s collection efforts for student unpaid meal charges and outlines the procedure used to write off unallowable bad debt.
A4: 1. Procurement/Purchasing Policies AND Procedures
A5: 2. Written Code of Conduct/Conflict of Interest Policy (related to food service procurement/contract awards; may be part of the Procurement/Purchasing policies)
A6: 3. Small Purchase Thresholds (may be part of the Procurement/Purchasing policies and/or procedures)
A7: 4. Bid Protest Policy or Procedure (may be part of the Procurement/Purchasing policies and/or procedures)
A8: 5. Meal Charge Policy (required even if all meals are free to students)
A9: 6. Bad Debt Policy (required even if all meals are free to students)
A11: Sponsor must attach a sample 21-day cycle menu for each meal (breakfast, lunch, snack, supper) served.
A13: 1. Include applicable menus for each site and grade level for:
B14: a. SNP breakfast, lunch and snack
B15: b. CACFP breakfast, lunch, snack, and supper
B16: c. Vended meals provided to other sites, such as Headstart
A17: 2. Menus must meet food specifications and meal patterns.
A18: 3. Menus must specify AT LEAST TWO milk choices (for SNP) and indicate all juice served is 100% vegetable/fruit juice.
A19: 4. Menus must show 21 or more days of meals being served to students.
A20: 5. Remove all food service logos and names of staff/directors.
A21: 6. These menus MUST be used for the first 21-day cycle of the new school year.
A23: Sponsor must attach A la Carte information (if applicable).
A25: Attach a separate PDF of the a la carte items/pricing sheet for each site where a la carte is available.
A27: Note: If the school sponsor is or will be a participant of the Fresh Fruit and Vegetable Program (FFVP), the bidder must submit a FFVP cycle menu based on FNS guidance as a part of its proposal.

Sheet 3-Food Specifications
A1: FOOD SPECIFICATIONS FOR CHILD NUTRITION PROGRAMS
A2: Specific food requirements (such as peanut-free, Halal, Kosher, etc.) (sponsor completes):
A4: Specific food quality requirements (such as lean meat, fresh vs. canned fruit, type of buns, protein restrictions, etc.) (sponsor completes):
A7: 1. | B7: The USDA may update program requirements at any time.
A9: 2. | B9: The Company is responsible to adhere to the most current USDA guidance at the time of bid submission and must continuously ensure meals are in compliance with USDA requirements for the duration of the contract.
A11: 3. | B11: Sponsor must monitor the Company's compliance with these requirements in accordance with the terms set forth in the contract.
A13: 4. | B13: Each meal must include the appropriate serving of each required food component and must be consistent with the targeted dietary specifications for sodium, calories, saturated and trans fat.
A15: 5. | B15: Additional information about School Meals, Meal Pattern Requirements, Nutrition Standards, Regulations, Policy Memos, and Guidance Materials can be found at the following links:
A16: a. | B16: MDE-School Nutrition Programs-National School Lunch Program
A17: b. | B17: Nutrition Standards for School Meals | Food and Nutrition Service
A18: c. | B18: Certification of Compliance | Food and Nutrition Service
A19: d. | B19: NSLP Guidance and Resources | Food and Nutrition Service
A20: e. | B20: USDA Foods Available List for SY 2026-2027
A22: 6. | B22: While not inclusive, here are a few key USDA Policy memos that may be helpful:
A23: a. | B23: Updates to the School Nutrition Standards | Food and Nutrition Service
... A32: f. | B32: MDE-Food and Nutrition Programs-School Nutrition Programs-Fresh Fruit and Vegetable Program

Sheet Sample Non-Price Criteria 
A1: SAMPLE NON-PRICE CRITERIA AND SUB-CRITERIA (for Bid Point Calculator)
A2: Budget Forecasting and Costs
B3: Financial reports for revenue and costs (monthly, quarterly, etc.)
B4: Methods used to monitor food and non-food costs
B5: Methods used to monitor labor costs
B6: Plan for monitoring costs, financial reporting, and forecasting
B7: Recommendations made to adjust forecast
A9: District-Specific Requirements
B10: Experience in kitchen/food service layout and design (renovation or new construction)
B11: Experience providing catering services outside the school district (Head Start, Meals on Wheels, adult daycare, community centers, child daycare, etc.)
B12: Experience working with Farm to School programming, including Farm to School grants, education, and local purchasing
B13: Experience working with Point of Service (POS) systems (technological support/back-up)
B14: Experience working with various types of food preparation and delivery systems (Quick Chill, satelliting, unitized meals, etc.)
A16: Employee Training and Development
B17: Examples of training materials used for foodservice employees
B18: Food safety and sanitation training/Hazard Analysis and Critical Control Points (HACCP)
B19: Portion control and quantity food production
B20: Professional development provided for on-site manager
B21: Training program for foodservice employees
B22: Work safety (lifting, bending, cutting, slicing, etc.)
A24: Food Service Manager/Director Candidate
B25: Experience conducting procurement
B26: Experience staffing K-12 food service programs
B27: Experience with menu development and special events
B28: Experience working collaboratively with various school personnel (i.e., wellness programs)
B29: Experience working in school foodservice (i.e., five years or more)
B30: Experience working with USDA Foods
B31: Knowledge and ability to work with union employees and collective bargaining agreements
B32: Professional development provided to food service manager/director candidate (workshops, continuing education, etc.)
A34: Nutrition Education
B35: Ability to incorporate district's wellness plan in menu choices offered
B36: Alternate menu choices/offerings (i.e., low fat, low sodium)
B37: Collaborative nutrition education/wellness program efforts done with other school districts
B38: Promotional materials (posters, menus, flyers, etc.)
B39: Samples/examples of materials used to promote healthy messages/making healthy choices
A41: Past Performance
B42: Results of Administrative Review (AR)
B43: Results of local health and safety inspection report
A45: Plan to Increase Participation
B46: Alternate menu choices/offerings
...

Sheet Sample Bid Point Calculator
A1: This sample demonstrates how the sponsor should format the non-price criteria on the bid point calculator. The sponsor should not use the exact non-price criteria listed here, but should use specific factors it will use to make its decision for award.
A2: BID POINT CALCULATOR AND EVALUATION CRITERIA MATRIX (to be completed by School Sponsor)
A3: NAME OF SCHOOL SPONSOR
A4: Total Maximum Points is 100. Highest number of points wins the award. | D4: Company Name
A6: Bid Calculation and Evaluation Criteria | D6: Enter Bid Price lowest to highest
A7: Enter Bid Price from lowest to highest >>>>>>>>>>>>
A8: Subtract lowest bid from bid above | D8: 0 | E8: =+E7-D7 -> 0 | F8: =+F7-D7 -> 0 | G8: =+G7-D7 -> 0 | H8: =+H7-D7 -> 0 | I8: =+I7-D7 -> 0
A9: Divide answer from above by lowest bid | D9: 0 | E9: =+E8/D7 -> #DIV/0! | F9: =+F8/D7 -> #DIV/0! | G9: =+G8/$D$7 -> #DIV/0! | H9: =+H8/$D$7 -> #DIV/0! | I9: =+I8/$D$7 -> #DIV/0!
A10: Subtract answer above from 1 | D10: =ROUND(1-D9,2) -> 1 | E10: =1-E9 -> #DIV/0! | F10: =1-F9 -> #DIV/0! | G10: =1-G9 -> #DIV/0! | H10: =1-H9 -> #DIV/0! | I10: =1-I9 -> #DIV/0!
A11: 51 | B11: Multiply answer above by 51 or more | D11: =+D10*51 -> 51 | E11: =+E10*51 -> #DIV/0! | F11: =(F10*51) -> #DIV/0! | G11: =+G10*0.51*100 -> #DIV/0! | H11: =+H10*0.51*100 -> #DIV/0! | I11: =+I10*0.51*100 -> #DIV/0!
A12: Points Assigned | C12: List Non-Price Criteria and Sub-criteria Below (points will total 100 when added to Bid Price Points) | D12: Enter Evaluation Points
A13: 4 | C13: Proposal Size
B14: 4 | C14: FSMC's bid proposal is 200 pages or less
A15: 6 | C15: Reference Checks | K15: Do not copy and paste these sample non-price criteria and sub-criteria items onto your own Bid Point Calculator. These are meant to be shown as examples for formatting only.
B16: 3 | C16: Relationship/communication with the school district
B17: 3 | C17: Student/staff/parent satisfaction with quality, appearance, and taste of food served
A18: 8 | C18: District-Specific Requirements
B19: 3 | C19: Experience providing catering/vended meal services outside the district
B20: 3 | C20: Experience in kitchen/food service layout and design for new construction projects
B21: 2 | C21: Experience working with Farm to School programming, including Farm to School grants, education, and local purchasing
A22: 6 | C22: Plan to Increase Participation
B23: 2 | C23: Description of methods to obtain and plans to use student/staff/parent feedback/preferences
B24: 2 | C24: Innovative ways of providing quick and efficient service
B25: 2 | C25: Innovative ways of promoting breakfast and lunch programs
A26: 4 | C26: Plan for Marketing and Merchandising
B27: 2 | C27: Recognition of holidays and special events
B28: 2 | C28: Use of promotions/promotional events (posters, theme days, student taste testing)
A29: 7 | C29: Operation Recommendations
B30: 3 | C30: Equipment recommendations and provisions (new equipment, use of current equipment, etc.)
B31: 4 | C31: Facility layout/design recommendations in relation to proposed menu and population being served
A32: 4 | C32: Nutrition Education
B33: 2 | C33: Samples/examples of materials used to promote healthy messages/making healthy choices
B34: 2 | C34: Alternate menu choices/offerings (i.e., low fat, low sodium)
A35: 4 | C35: Employee Training and Development
B36: 2 | C36: Food safety and sanitation training
B37: 2 | C37: Work safety (lifting, bending, cutting, slicing, etc.)
A38: 6 | C38: Support by FSMC Area Manager
B39: 2 | C39: Frequency of area manager presence at the district (at least once per week)
B40: 2 | C40: Ease and ability to travel to district upon request (lives within 50 miles of district)
B41: 2 | C41: Knowledge and ability to work with union employees
...

Sheet 4-Bid Point Calculator
A1: BID POINT CALCULATOR AND EVALUATION CRITERIA MATRIX (to be completed by School Sponsor)
A2: NAME OF SCHOOL SPONSOR
A3: Total Maximum Points is 100. Highest number of points wins the award. | D3: Company Name
A5: Bid Calculation and Evaluation Criteria | D5: Enter Bid Price lowest to highest
A6: Enter Bid Price from lowest to highest >>>>>>>>>>>
A7: Subtract lowest bid from bid above | D7: 0 | E7: =+E6-D6 -> 0 | F7: =+F6-D6 -> 0 | G7: =+G6-D6 -> 0 | H7: =+H6-D6 -> 0 | I7: =+I6-D6 -> 0
A8: Divide answer from above by lowest bid | D8: 0 | E8: =+E7/D6 -> #DIV/0! | F8: =+F7/D6 -> #DIV/0! | G8: =+G7/$D$6 -> #DIV/0! | H8: =+H7/$D$6 -> #DIV/0! | I8: =+I7/$D$6 -> #DIV/0!
A9: Subtract answer above from 1 | D9: =ROUND(1-D8,2) -> 1 | E9: =1-E8 -> #DIV/0! | F9: =1-F8 -> #DIV/0! | G9: =1-G8 -> #DIV/0! | H9: =1-H8 -> #DIV/0! | I9: =1-I8 -> #DIV/0!
A10: 51 | B10: Multiply answer above by 51 or more | D10: =+D9*51 -> 51 | E10: =+E9*51 -> #DIV/0! | F10: =(F9*51) -> #DIV/0! | G10: =+G9*0.51*100 -> #DIV/0! | H10: =+H9*0.51*100 -> #DIV/0! | I10: =+I9*0.51*100 -> #DIV/0! | M10: Example for Formatting
A11: Points Assigned | C11: List Non-Price Criteria and Sub-criteria Below (points will total 100 when added to Bid Price Points) | D11: Enter Evaluation Points | M11: Points Assigned | O11: List Non-Price Criteria and Sub-criteria Below (points will total 100 when added to Bid Price Points)
M12: 6 | O12: Reference Checks
N13: 3 | O13: Relationship/communication with the school district
N14: 3 | O14: Student/staff/parent satisfaction with quality, appearance, and taste of food served
M15: 8 | O15: District-Specific Requirements
N16: 3 | O16: Experience providing catering/vended meal services outside the district
N17: 3 | O17: Experience in kitchen/food service layout and design for new construction projects
N18: 2 | O18: Experience working with Farm to School programming
A42: =SUM(A10,A16:A41) -> 51 | C42: TOTAL | D42: =SUM(D10:D41) -> 51 | E42: =SUM(E10:E41) -> #DIV/0! | F42: =SUM(F10:F41) -> #DIV/0! | G42: =SUM(G10:G41) -> #DIV/0! | H42: =SUM(H10:H41) -> #DIV/0! | I42: =SUM(I10:I41) -> #DIV/0!

Sheet 5-Equipment List
A1: EQUIPMENT INVENTORY LIST (to be completed by School Sponsor)
A2: List all food service equipment used in food service and identify if it belongs to the sponsor or if it is an FSMC-provided item.
B3: Mark an "X" in the appropriate columns for each item.
A4: Equipment List by Site | B4: Expendable (one time use) | C4: Non-Expendable (reusable) | D4: Sponsor Owns | E4: FSMC Provides
G14: EXAMPLE for formatting only - do not copy and paste
G15: Equipment List by Site | H15: Expendable | I15: Non-Expendable | J15: Sponsor Owns | K15: FSMC Provides
G16: District
G17: Food delivery box truck | I17: X | J17: X
G18: Delivery van | I18: X | J18: X
G19: High School
G20: Four burner stove with oven | I20: X | J20: X
G21: Two-door freezer | I21: X | J21: X
G22: Refrigerator (2) | I22: X | J22: X
G23: Milk cooler (12 crate) | I23: X | J23: X
G24: Milk cooler (12 crate) | I24: X | K24: X
G25: Three-pan steamer (2) | I25: X | J25: X
G26: Slushie Machine | I26: X | J26: X
G27: Toaster | I27: X | J27: X
G28: Microwave | I28: X | J28: X
G29: Cookware, bakeware, cookie sheets, etc. | I29: X | J29: X
G30: Metal and plastic mixing and serving bowls | I30: X | J30: X
G31: Serving utensils | I31: X | J31: X
G32: Stainless steel carts (4) | I32: X | J32: X
G33: Hairnets, face masks, gloves | H33: X | J33: X
G34: Middle School
G35: Four burner stove with oven | I35: X | J35: X
G36: Two-door freezer | I36: X | J36: X
G37: Refrigerator | I37: X | J37: X
G38: Milk cooler (12 crate) | I38: X | J38: X
G39: Three-pan steamer | I39: X | J39: X
G40: Microwave | I40: X | J40: X
G41: Cookware, bakeware, cookie sheets, etc. | I41: X | J41: X
G42: Metal and plastic mixing and serving bowls | I42: X | J42: X
G43: Serving utensils | I43: X | J43: X
G44: Stainless steel carts (2) | I44: X | J44: X
G45: Hairnets, face masks, gloves | H45: X | J45: X
G46: Elementary School
G47: Milk cooler (12 crate) | I47: X | J47: X
G48: Serving utensils | I48: X | J48: X
G49: Plastic cart | I49: X | J49: X
...

Sheet 6-VendedContractsAgrmts
A1: VENDED CONTRACTS/AGREEMENTS (to be completed by School Sponsor)
A2: CATERING SERVICE CONTRACTS/AGREEMENTS: List sites/entities that receive catered/vended meals via a catering service contract or agreement (such as a head start or great start readiness program, child or adult daycare center, juvenile detention center, Meals on Wheels, church group, etc.).
A3: Name of Site/Entity | B3: Site/Entity Street Address City, Zip Code | C3: Approximate Number of Meals Provided DAILY | G3: Anticipated Yearly Dollar ($) Value of Contract
C4: Breakfast | D4: Lunch | E4: Snack | F4: Supper
F10: TOTAL* | G10: =SUM(G5:G9) -> 0
A11: *The total dollar value will transfer to the Projected Revenue tab under Local Revenue/Catering Service Contracts/Agreements.
A14: ALTERNATE AGREEMENTS: List sites that receive vended meals via an alternate agreement. Include program meal details on Sites and Programs tab 7. NOTE: An alternate agreement is where one school district becomes a site under another district. The receiving district is considered the local education authority (LEA), and they get their meals delivered by the other district, who is the sponsor. The sponsor manages the LEA’s food program and includes the LEA as a site in their own coordinated application. The sponsor claims the meals and receives the reimbursements.
A15: Name of LEA | B15: Name of Site(s) | C15: Site Street Address City, Zip Code
A24: VENDED MEALS CONTRACT: List sites that receive vended meals via a vended meals contract. Include program meal details on Sites and Programs tab 7. NOTE: With a vended meals contract, one sponsor is awarded a contract from another sponsor that went through the contract bid process to procure vended meals. The contract will indicate a price per meal fee paid to the vending sponsor by the receiving sponsor. The receiving sponsor manages and oversees its own food service program, does its own coordinated application, claims its own meals and receives the reimbursements. Per contract terms, the vending sponsor provides meals and supplies to the receiving sponsor. The contract may or may not include meal delivery and/or servers.
A25: Name of Receiving Sponsor | B25: Name of Site(s) | C25: Site Street Address City, Zip Code

Sheet 8-USDA Foods
A1: USDA FOODS INFORMATION (to be completed by School Sponsor)
A3: School Sponsor will include the most recent Year-End PAL Report in the bid packet.
A5: Next School Year's Consortia Election:
A6: Last School Year's Total Delivery Fee Amount:
A7: Describe any major changes that took place in the district in the last two years that might have impacted USDA Food Entitlement Usage. For example, did the district's special dietary needs change or enrollment increase/decrease significantly?

Sheet 7-Sites and Programs
A1: SITE DEMOGRAPHICS AND PROGRAM PARTICIPATION (to be completed by School Sponsor)
A2: List ALL sites that serve meals. Enter beginning and ending service times and X as appropriate. *Indicate either Full Serve OR Offer vs. Serve, NOT both. For grades 9-12, lunch must be Offer vs. Serve. If a site includes some grades that do Full Serve and some grades that do Offer vs. Serve, list those grades on separate lines and label accordingly.
A3: Site Name List all sites that serve meals, including those sites indicated on Tab 6 for Vended Contracts/Agreements. | B3: Indicate Site's Claiming Status (X as appropriate) | F3: Site Street Address City, Zip Code | G3: Grade Levels | H3: Total Enrollment Number | I3: Self-Prep OR Receives Satellite/Vended Meals (list site that prepares meals) | J3: SNP Breakfast | O3: SNP Lunch | T3: SNP After School Snack (X) | U3: FFVP (X) | V3: CACFP | Z3: SFSP | AD3: Special Milk Program (X)
B4: Own Site - this sponsor claims | C4: Catering Service Contract/Agrmt - other sponsor may or may not claim | D4: Alternate Agreement - this sponsor claims | E4: Vended Meals Contract - other sponsor claims | J4: Full Serve* (X) | K4: Offer vs Serve* (X) | L4: BREAKFAST Beginning and Ending Service Times | M4: A la Carte (X) | N4: Adult Meals (X) | O4: Full Serve* (X) | P4: Offer vs Serve* (X) | Q4: LUNCH Beginning and Ending Service Times | R4: A la Carte (X) | S4: Adult Meals (X) | V4: BREAKFAST Beginning and Ending Service Times | W4: LUNCH Beginning and Ending Service Times | X4: SNACK Beginning and Ending Service Times | Y4: SUPPER Beginning and Ending Service Times | Z4: BREAKFAST (X) | AA4: LUNCH (X) | AB4: SNACK (X) | AC4: SUPPER (X)

Sheet 9-Responsibility Details
A1: RESPONSIBILITY DETAILS (to be completed by School Sponsor)
A2: RESPONSIBILITY | D2: SPONSOR (X) | E2: FSMC (X) | F2: N/A (X)
A3: Cleaning
B4: Preparation/Serving Areas
B5: Kitchen Floors
B6: Kitchen Restrooms
B7: Hoods, Duct Work
B8: Grease Traps
B9: Light Fixtures
B10: Routine Cleaning of Cafeteria Tables and Chairs
B11: Cafeteria Floors
B12: Cafeteria Walls
B13: Windows
A14: Food
B15: Food Purchases
B16: USDA Foods/Commodity Delivery and Processing Charges
A17: Labor/Benefits - Processing and Payment of Payroll
B18: Managers and/or Supervisors (salaried)
B19: Full and Part-time Workers (hourly)
B20: Monitors (employed or contracted)
A21: Other Expenses
B22: Accounting
C23: Bank Charges
C24: Data Processing
C25: Recordkeeping
C26: Processing and Payment of Invoices
B27: Cleaning/Janitorial Supplies
B28: Equipment - Major
C29: Original Purchase
C30: Routine Maintenance
C31: Major Repairs
C32: Replacement
B33: Equipment - Expendable (i.e., trays, tableware, utensils, etc.)
C34: Original Purchase
C35: Routine Maintenance
C36: Major Repairs
C37: Replacement
B38: Insurance
C39: Liability Insurance
C40: Insurance on Supplies/Inventory
...

Sheet 10-Current Labor-Fringe
A1: CURRENT OPERATIONS - LABOR AND FRINGE BENEFITS WORKSHEET School Year 2025-2026 (Current) (to be completed by School Sponsor)
A2: *Include staffing for ALL programs (CACFP, SFSP, SNP). **Include paid time off (PTO), holiday pay, and sick pay.
A3: Enter labor and fringe benefit costs for all Sponsor-Employed Hourly/Salaried Staff in this section. Insert additional rows as needed.
A4: Site or School Building | B4: Job Title* | C4: Hourly Rate ($) | D4: Daily Hours | E4: Number of Days Paid | F4: Total Annual Wage ($) | G4: Medical | H4: Dental | I4: Vision | J4: Longevity or Annuity | K4: Life | L4: Retirement | M4: FICA | N4: Other** | O4: Total Fringe
C5: 0 | F5: =C5*D5*E5 -> 0 | G5: 0 | H5: 0 | I5: 0 | J5: 0 | K5: 0 | L5: 0 | M5: 0 | N5: 0 | O5: =SUM(G5:N5) -> 0
C6: 0 | F6: =C6*D6*E6 -> 0 | G6: 0 | H6: 0 | I6: 0 | J6: 0 | K6: 0 | L6: 0 | M6: 0 | N6: 0 | O6: =SUM(G6:N6) -> 0
C7: 0 | F7: =C7*D7*E7 -> 0 | G7: 0 | H7: 0 | I7: 0 | J7: 0 | K7: 0 | L7: 0 | M7: 0 | N7: 0 | O7: =SUM(G7:N7) -> 0
C8: 0 | F8: =C8*D8*E8 -> 0 | G8: 0 | H8: 0 | I8: 0 | J8: 0 | K8: 0 | L8: 0 | M8: 0 | N8: 0 | O8: =SUM(G8:N8) -> 0
C9: 0 | F9: =C9*D9*E9 -> 0 | G9: 0 | H9: 0 | I9: 0 | J9: 0 | K9: 0 | L9: 0 | M9: 0 | N9: 0 | O9: =SUM(G9:N9) -> 0
C10: 0 | F10: =C10*D10*E10 -> 0 | G10: 0 | H10: 0 | I10: 0 | J10: 0 | K10: 0 | L10: 0 | M10: 0 | N10: 0 | O10: =SUM(G10:N10) -> 0
C11: 0 | F11: =C11*D11*E11 -> 0 | G11: 0 | H11: 0 | I11: 0 | J11: 0 | K11: 0 | L11: 0 | M11: 0 | N11: 0 | O11: =SUM(G11:N11) -> 0
C12: 0 | F12: =C12*D12*E12 -> 0 | G12: 0 | H12: 0 | I12: 0 | J12: 0 | K12: 0 | L12: 0 | M12: 0 | N12: 0 | O12: =SUM(G12:N12) -> 0
C13: 0 | F13: =C13*D13*E13 -> 0 | G13: 0 | H13: 0 | I13: 0 | J13: 0 | K13: 0 | L13: 0 | M13: 0 | N13: 0 | O13: =SUM(G13:N13) -> 0
C14: 0 | F14: =C14*D14*E14 -> 0 | G14: 0 | H14: 0 | I14: 0 | J14: 0 | K14: 0 | L14: 0 | M14: 0 | N14: 0 | O14: =SUM(G14:N14) -> 0
C15: 0 | F15: =C15*D15*E15 -> 0 | G15: 0 | H15: 0 | I15: 0 | J15: 0 | K15: 0 | L15: 0 | M15: 0 | N15: 0 | O15: =SUM(G15:N15) -> 0
C16: 0 | F16: =C16*D16*E16 -> 0 | G16: 0 | H16: 0 | I16: 0 | J16: 0 | K16: 0 | L16: 0 | M16: 0 | N16: 0 | O16: =SUM(G16:N16) -> 0
... C23: 0 | F23: =C23*D23*E23 -> 0 | G23: 0 | H23: 0 | I23: 0 | J23: 0 | K23: 0 | L23: 0 | M23: 0 | N23: 0 | O23: =SUM(G23:N23) -> 0
A24: District-wide | B24: Sponsor's Total Annual Substitute Pay | F24: 0
B25: TOTAL - Sponsor's Hourly/Salaried Staff Labor and Fringe Benefit Costs | F25: =SUM(F5:F24) -> 0 | G25: =SUM(G5:G24) -> 0 | H25: =SUM(H5:H24) -> 0 | I25: =SUM(I5:I24) -> 0 | J25: =SUM(J5:J24) -> 0 | K25: =SUM(K5:K24) -> 0 | L25: =SUM(L5:L24) -> 0 | M25: =SUM(M5:M24) -> 0 | ... O25: =SUM(O5:O24) -> 0
A26: Enter labor and fringe benefit costs for all FSMC-Employed Hourly Staff in this section. Insert additional rows as needed.
A27: Site or School Building | B27: Job Title* | C27: Hourly Rate ($) | D27: Daily Hours | E27: Number of Days Paid | F27: Total Annual Wage ($) | G27: Medical | H27: Dental | I27: Vision | J27: Longevity or Annuity | K27: Life | L27: Retirement | M27: FICA | N27: Other** | O27: Total Fringe
C28: 0 | F28: =C28*D28*E28 -> 0 | G28: 0 | H28: 0 | I28: 0 | J28: 0 | K28: 0 | L28: 0 | M28: 0 | N28: 0 | O28: =SUM(G28:N28) -> 0
C29: 0 | F29: =C29*D29*E29 -> 0 | G29: 0 | H29: 0 | I29: 0 | J29: 0 | K29: 0 | L29: 0 | M29: 0 | N29: 0 | O29: =SUM(G29:N29) -> 0
C30: 0 | F30: =C30*D30*E30 -> 0 | G30: 0 | H30: 0 | I30: 0 | J30: 0 | K30: 0 | L30: 0 | M30: 0 | N30: 0 | O30: =SUM(G30:N30) -> 0
C31: 0 | F31: =C31*D31*E31 -> 0 | G31: 0 | H31: 0 | I31: 0 | J31: 0 | K31: 0 | L31: 0 | M31: 0 | N31: 0 | O31: =SUM(G31:N31) -> 0
C32: 0 | F32: =C32*D32*E32 -> 0 | G32: 0 | H32: 0 | I32: 0 | J32: 0 | K32: 0 | L32: 0 | M32: 0 | N32: 0 | O32: =SUM(G32:N32) -> 0
C33: 0 | F33: =C33*D33*E33 -> 0 | G33: 0 | H33: 0 | I33: 0 | J33: 0 | K33: 0 | L33: 0 | M33: 0 | N33: 0 | O33: =SUM(G33:N33) -> 0
C34: 0 | F34: =C34*D34*E34 -> 0 | G34: 0 | H34: 0 | I34: 0 | J34: 0 | K34: 0 | L34: 0 | M34: 0 | N34: 0 | O34: =SUM(G34:N34) -> 0
C35: 0 | F35: =C35*D35*E35 -> 0 | G35: 0 | H35: 0 | I35: 0 | J35: 0 | K35: 0 | L35: 0 | M35: 0 | N35: 0 | O35: =SUM(G35:N35) -> 0
C36: 0 | F36: =C36*D36*E36 -> 0 | G36: 0 | H36: 0 | I36: 0 | J36: 0 | K36: 0 | L36: 0 | M36: 0 | N36: 0 | O36: =SUM(G36:N36) -> 0
C37: 0 | F37: =C37*D37*E37 -> 0 | G37: 0 | H37: 0 | I37: 0 | J37: 0 | K37: 0 | L37: 0 | M37: 0 | N37: 0 | O37: =SUM(G37:N37) -> 0
C38: 0 | F38: =C38*D38*E38 -> 0 | G38: 0 | H38: 0 | I38: 0 | J38: 0 | K38: 0 | L38: 0 | M38: 0 | N38: 0 | O38: =SUM(G38:N38) -> 0
C39: 0 | F39: =C39*D39*E39 -> 0 | G39: 0 | H39: 0 | I39: 0 | J39: 0 | K39: 0 | L39: 0 | M39: 0 | N39: 0 | O39: =SUM(G39:N39) -> 0
... C47: 0 | F47: =C47*D47*E47 -> 0 | G47: 0 | H47: 0 | I47: 0 | J47: 0 | K47: 0 | L47: 0 | M47: 0 | N47: 0 | O47: =SUM(G47:N47) -> 0
A48: District-wide | B48: FSMC's Total Annual Substitute Pay | F48: 0
B49: TOTAL - FSMC's Hourly Staff Labor and Fringe Benefit Costs | F49: =SUM(F28:F48) -> 0 | G49: =SUM(G28:G48) -> 0 | H49: =SUM(H28:H48) -> 0 | I49: =SUM(I28:I48) -> 0 | J49: =SUM(J28:J48) -> 0 | K49: =SUM(K28:K48) -> 0 | L49: =SUM(L28:L48) -> 0 | M49: =SUM(M28:M48) -> 0 | ... O49: =SUM(O28:O48) -> 0
A50: Enter the TOTAL labor and fringe benefit cost for all FSMC-employed Salaried Management Staff in this section (i.e., director, assistant director, chef, administrative assistant, etc.). Insert additional rows as needed.
A51: Site or School Building | B51: Job Title* | C51: Enter TOTAL below for annual wages and fringe benefit costs for all salaried management employees combined. Do not enter costs separately for each management employee.
F56: Total Annual Wage ($) | G56: Total Fringe
B58: TOTAL - FSMC's Management Staff Labor and Fringe Benefit Costs

Sheet 11-Projected Costs
A1: PROJECTED COSTS FOR SY 2026-2027 (to be completed by School Sponsor)
A2: Projected costs are based on ____ days of service in SY 2025-2026.
A3: FOOD SERVICE ACCOUNT EXPENSES | B3: TOTAL PROJECTED ANNUAL COST (for SY 26-27) | C3: Not a Bid Item (X)
B4: Cells will auto-fill
A5: SFA Employees Labor Cost | B5: =SUM('10-Current Labor-Fringe'!F25) -> 0
A6: SFA Employees Fringe Benefit Cost | B6: =SUM('10-Current Labor-Fringe'!O25) -> 0
A7: FSMC Hourly Employees Labor Cost | B7: =SUM('10-Current Labor-Fringe'!F49) -> 0
A8: FSMC Hourly Employees Fringe Benefit Cost | B8: =SUM('10-Current Labor-Fringe'!O49) -> 0
A9: FSMC On-Site Management Employees Labor Cost | B9: =SUM('10-Current Labor-Fringe'!F58) -> 0
A10: FSMC On-Site Management Employees Fringe Benefit Cost | B10: =SUM('10-Current Labor-Fringe'!G58) -> 0
A11: Food Cost for SNP, CACFP, and SFSP Meals (including commodities delivery charge)
A12: Non-Food Cost for SNP, CACFP, and SFSP (supplies and other materials)
A13: Food Cost for FFVP
A14: Non-Food Cost for FFVP (supplies and other materials)
A15: Contracted Services (not including FSMC administrative and management fees) (insert detail, such as pest control, lunchroom monitors, equipment repairs and maintenance, etc.)
A16: Transportation/Vehicle Costs (fuel, maintenance, repairs)
A17: Utilities (assigned to Food Service Fund)
A18: Indirect Costs (assigned to Food Service Fund)
A19: Other Expenses (insert detail)
A22: Total Projected Expenses for SY 2026-2027 | B22: =SUM(B5:B21) -> 0

Sheet 12-Projected Revenue
A1: PROJECTED REVENUE FOR SY 2026-2027 (to be completed by District/Sponsor and MDE)
A2: MDE will enter the yearly projections for the number sold amounts, which are based on claims for the month(s) of October 2025 for SNP/CACFP and June/July/August 2025 for SFSP.
A3: Projected total number of days for the 2026-2027 school year | C3: Breakfast Days | F3: Lunch Days | G3: Snack Days | H3: Supper Days
A4: School Nutrition Programs (SNP) | H4: n/a
A5: Child and Adult Care Food Program (CACFP)
A6: Summer Food Service Program (SFSP)
A7: LOCAL REVENUE | B7: Projected Number Sold | C7: Student/Adult Meal Rate | F7: Total
A8: Breakfast - SNP
A9: Elementary Paid | C9: x | E9: = | G9: All student meals are free.
A10: Secondary Paid | C10: x | E10: =
A11: Reduced | C11: x | D11: 0.3 | E11: =
F12: Subtotal Paid Breakfast | G12: =SUM(F9:F11) -> 0
A13: Lunch - SNP
A14: Elementary Paid | C14: x | E14: = | G14: All student meals are free.
A15: Secondary Paid | C15: x | E15: =
A16: Reduced | C16: x | D16: 0.4 | E16: =
F17: Subtotal Paid Lunch | G17: =SUM(F14:F16) -> 0
A18: Special Milk Program
A19: Elementary Paid | C19: x | E19: =
A20: Secondary Paid | C20: x | E20: =
F21: Subtotal Paid Special Milk | G21: =SUM(F19:F20) -> 0
A22: Other Local Revenue - Sponsor enter the projections for the 26-27 school year
A23: Adult Breakfast Meals | C23: x | E23: = | F23: =+B23*D23 -> 0 | G23: THESE ARE PROJECTIONS FOR THE YEAR | K23: DO NOT ALTER - CELLS WILL AUTO-FILL
A24: Adult Lunch Meals | C24: x | E24: = | F24: =+B24*D24 -> 0 | K24: Federal Free Lunch Rate | L24: 4.69
A25: A la Carte Sales - Elementary | F25: 0 | K25: + Commodity Entitlement Rate | L25: 0.45
A26: A la Carte Sales - Secondary | F26: 0 | K26: Total | L26: =SUM(L24:L25) -> 5.14
A27: Concessions | F27: 0 | K27: Other Local Revenue | L27: =SUM(G33) -> 0
A28: Vending Machines | F28: 0 | K28: Non-Program Meal Equivalents (divide Other Local Revenue by Total) | L28: =+L27/L26 -> 0
A29: Catering | F29: 0
A30: Vended Contracts (see Contracts/Vended Agreements tab) | F30: 0 | K30: Total Breakfasts Served (2:1) | L30: =SUM(B43,B62,B82)/2 -> 0
A31: Summer Programs (not SFSP) | F31: 0 | K31: Total Lunches Served (1:1) | L31: =SUM(B51,B67,B86) -> 0
A32: Other (describe) | F32: 0 | K32: Total Snacks Served (3:1) | L32: =SUM(B56,B72,B90)/3 -> 0
F33: Subtotal Other Local Revenue | G33: =SUM(F23:F32) -> 0 | K33: Total Suppers Served (1:1) | L33: =SUM(B77,B94) -> 0
G34: Total Local Revenue | H34: =SUM(G12,G17,G21,G33) -> 0 | K34: Program Meal Equivalents | L34: =SUM(L30:L33) -> 0
A35: REIMBURSEMENTS | B35: Projected Number Sold | D35: Federal Rates for SY 25-26 | F35: Total | K35: TOTAL PROJECTED MEALS/MEAL EQUIVALENTS | L35: =SUM(L28,L34) -> 0
A36: School Nutrition Programs (SNP)
A37: Breakfast
A38: Free | C38: x | D38: 2.46 | E38: = | F38: =+B38*D38 -> 0
A39: Free, severe need | C39: x | D39: 2.94 | E39: = | F39: =+B39*D39 -> 0
A40: Reduced | C40: x | D40: 2.16 | E40: = | F40: =+B40*D40 -> 0
...

Sheet 13-FSMC Proposed Labor-Fringe
A1: PROPOSED OPERATIONS - FSMC LABOR AND FRINGE BENEFITS WORKSHEET School Year 2026-2027 (to be completed by Bidder)
A2: NOTE: To be competitively fair and equal, please note that bidders are NOT allowed to be over-responsive in any proposed management staffing structure. For example, if the sponsor does not ask for an assistant food service director in the RFP, then the FSMC must not propose one. Bidders may submit staffing questions to the sponsor by the Q&A deadline so responses can be distributed fairly among all potential bidders to ensure a competitively fair and equal bidding opportunity (i.e., whether a sponsor would like bids to include an assistant director).
A3: *Include staffing for ALL programs (CACFP, SFSP, SNP). **Include paid time off (PTO), holiday pay, and sick pay.
A4: Enter labor and fringe benefit costs for all FSMC-Employed Hourly Staff in this section. Insert additional rows as needed.
A5: Site or School Building | B5: Job Title* | C5: Hourly Rate ($) | D5: Daily Hours | E5: Number of Days Paid | F5: Total Annual Wage ($) | G5: Medical | H5: Dental | I5: Vision | J5: Longevity or Annuity | K5: Life | L5: Retirement | M5: FICA | N5: Other** | O5: Total
C6: 0 | F6: =C6*D6*E6 -> 0 | G6: 0 | H6: 0 | I6: 0 | J6: 0 | K6: 0 | L6: 0 | M6: 0 | N6: 0 | O6: =SUM(G6:N6) -> 0
C7: 0 | F7: =C7*D7*E7 -> 0 | G7: 0 | H7: 0 | I7: 0 | J7: 0 | K7: 0 | L7: 0 | M7: 0 | N7: 0 | O7: =SUM(G7:N7) -> 0
C8: 0 | F8: =C8*D8*E8 -> 0 | G8: 0 | H8: 0 | I8: 0 | J8: 0 | K8: 0 | L8: 0 | M8: 0 | N8: 0 | O8: =SUM(G8:N8) -> 0
C9: 0 | F9: =C9*D9*E9 -> 0 | G9: 0 | H9: 0 | I9: 0 | J9: 0 | K9: 0 | L9: 0 | M9: 0 | N9: 0 | O9: =SUM(G9:N9) -> 0
C10: 0 | F10: =C10*D10*E10 -> 0 | G10: 0 | H10: 0 | I10: 0 | J10: 0 | K10: 0 | L10: 0 | M10: 0 | N10: 0 | O10: =SUM(G10:N10) -> 0
C11: 0 | F11: =C11*D11*E11 -> 0 | G11: 0 | H11: 0 | I11: 0 | J11: 0 | K11: 0 | L11: 0 | M11: 0 | N11: 0 | O11: =SUM(G11:N11) -> 0
C12: 0 | F12: =C12*D12*E12 -> 0 | G12: 0 | H12: 0 | I12: 0 | J12: 0 | K12: 0 | L12: 0 | M12: 0 | N12: 0 | O12: =SUM(G12:N12) -> 0
C13: 0 | F13: =C13*D13*E13 -> 0 | G13: 0 | H13: 0 | I13: 0 | J13: 0 | K13: 0 | L13: 0 | M13: 0 | N13: 0 | O13: =SUM(G13:N13) -> 0
C14: 0 | F14: =C14*D14*E14 -> 0 | G14: 0 | H14: 0 | I14: 0 | J14: 0 | K14: 0 | L14: 0 | M14: 0 | N14: 0 | O14: =SUM(G14:N14) -> 0
C15: 0 | F15: =C15*D15*E15 -> 0 | G15: 0 | H15: 0 | I15: 0 | J15: 0 | K15: 0 | L15: 0 | M15: 0 | N15: 0 | O15: =SUM(G15:N15) -> 0
C16: 0 | F16: =C16*D16*E16 -> 0 | G16: 0 | H16: 0 | I16: 0 | J16: 0 | K16: 0 | L16: 0 | M16: 0 | N16: 0 | O16: =SUM(G16:N16) -> 0
C17: 0 | F17: =C17*D17*E17 -> 0 | G17: 0 | H17: 0 | I17: 0 | J17: 0 | K17: 0 | L17: 0 | M17: 0 | N17: 0 | O17: =SUM(G17:N17) -> 0
... C25: 0 | F25: =C25*D25*E25 -> 0 | G25: 0 | H25: 0 | I25: 0 | J25: 0 | K25: 0 | L25: 0 | M25: 0 | N25: 0 | O25: =SUM(G25:N25) -> 0
A26: District-wide | B26: FSMC's Total Annual Substitute Pay | F26: 0
A27: TOTAL - FSMC's Hourly Staff Labor and Fringe Benefit Costs | F27: =SUM(F6:F26) -> 0 | G27: =SUM(G6:G25) -> 0 | H27: =SUM(H6:H25) -> 0 | I27: =SUM(I6:I25) -> 0 | J27: =SUM(J6:J25) -> 0 | K27: =SUM(K6:K25) -> 0 | L27: =SUM(L6:L25) -> 0 | M27: =SUM(M6:M25) -> 0 | N27: =SUM(N6:N25) -> 0 | O27: =SUM(O6:O25) -> 0
A28: Enter labor and fringe benefit costs for all FSMC-Employed Salaried Management Staff in this section (i.e., director, assistant director, chef, administrative assistant, etc.) Insert additional rows as needed.
A29: Site or School Building | B29: Job Title* | C29: Hourly Rate ($) | D29: Daily Hours | E29: Number of Days Paid | F29: Total Annual Wage ($) | G29: Medical | H29: Dental | I29: Vision | J29: Longevity or Annuity | K29: Life | L29: Retirement | M29: FICA | N29: Other** | O29: Total
C30: 0 | F30: =C30*D30*E30 -> 0 | G30: 0 | H30: 0 | I30: 0 | J30: 0 | K30: 0 | L30: 0 | M30: 0 | N30: 0 | O30: =SUM(G30:N30) -> 0
C31: 0 | F31: =C31*D31*E31 -> 0 | G31: 0 | H31: 0 | I31: 0 | J31: 0 | K31: 0 | L31: 0 | M31: 0 | N31: 0 | O31: =SUM(G31:N31) -> 0
C32: 0 | F32: =C32*D32*E32 -> 0 | G32: 0 | H32: 0 | I32: 0 | J32: 0 | K32: 0 | L32: 0 | M32: 0 | N32: 0 | O32: =SUM(G32:N32) -> 0
C33: 0 | F33: =C33*D33*E33 -> 0 | G33: 0 | H33: 0 | I33: 0 | J33: 0 | K33: 0 | L33: 0 | M33: 0 | N33: 0 | O33: =SUM(G33:N33) -> 0
C34: 0 | F34: =C34*D34*E34 -> 0 | G34: 0 | H34: 0 | I34: 0 | J34: 0 | K34: 0 | L34: 0 | M34: 0 | N34: 0 | O34: =SUM(G34:N34) -> 0
C35: 0 | F35: =C35*D35*E35 -> 0 | G35: 0 | H35: 0 | I35: 0 | J35: 0 | K35: 0 | L35: 0 | M35: 0 | N35: 0 | O35: =SUM(G35:N35) -> 0
A36: TOTAL - FSMC's Management Staff Labor and Fringe Benefit Costs | F36: =SUM(F30:F35) -> 0 | G36: =SUM(G30:G35) -> 0 | H36: =SUM(H30:H35) -> 0 | I36: =SUM(I30:I35) -> 0 | J36: =SUM(J30:J35) -> 0 | K36: =SUM(K30:K35) -> 0 | L36: =SUM(L30:L35) -> 0 | M36: =SUM(M30:M35) -> 0 | ... O36: =SUM(O30:O35) -> 0

Sheet 14-Bid Sheet with adv pmt
A1: BID SHEET FSMC Cost Reimbursable Contract WITH ADVANCE PAYMENT
A3: This bid is being offered by:
B4: Name of Food Service Management Company
A5: This bid is being offered to:
B6: Name of School Sponsor
A7: Projected Meals/Meal Equivalents Per Year: | C7: =SUM('12-Projected Revenue'!L35) -> 0 | D7: (do not alter, cell will auto-fill upon MDE review)
A9: Advance Payment is: (Sponsor completes) | B9: _____ Annual | C9: _____ One Time Only
A11: Proposed Advance Payment: (Bidder completes) | B11: $ | C11: Month/Day Annual Payment Due: (Bidder completes)
A12: Sponsor is contracting for the expenses indicated as Bid Items below | D12: Bid Items (Sponsor completes) | E12: Projected Operating Cost WITH Advance Payment (Bidder completes)
A13: Labor - On-Site FSMC Management Employees | D13: X
A14: Fringe Benefits - On-Site FSMC Management Employees | D14: X
A15: Labor - FSMC Hourly Employees
A16: Fringe Benefits - FSMC Hourly Employees
A17: Food Cost for SNP, CACFP, and SFSP Meals (including commodities delivery charge) (net of VDA/rebates)
A18: Non-Food Cost for SNP, CACFP, and SFSP (supplies and other materials) | G18: Bidder will use the correct column to indicate if fees will be billed over a 10-month period, 12-month period, or by cost per meal/meal equivalent. Do not indicate costs in all 3 columns for each fee.
A19: Food Cost for FFVP (as defined in RFP)
A20: Non-Food Cost for FFVP (supplies and other materials) (as defined in RFP)
A21: Contracted Services (not utilities or FSMC administrative costs) | G21: School Year 2026-2027 Rates [will match the current rates on the SY 27-28 Renewal Rate Agreement Form (if renewed)]
A22: Transportation/Vehicle Cost
A23: Utilities (assigned to Food Service Fund) | G23: COST PER MONTH | J23: or | K23: COST PER MEAL / MEAL EQUIVALENT
A24: Other (as defined on Projected Costs tab) | G24: Monthly Fee (10 months) | H24: or | I24: Monthly Fee (12 months)
A25: FSMC Administrative Fee | D25: X | F25: FSMC Administrative Fee | H25: or | J25: or
A26: FSMC Management Fee | D26: X | F26: FSMC Management Fee | H26: or | J26: or
A27: Subtotal (Bid Items Only) | E27: =SUM(E13:E26) -> 0
A28: Bid Price Per Meal (subtotal divided by projected meals/meal equivalents) | E28: =E27/C7 -> #DIV/0!
A29: Additional Food Service Markup if applicable (refer to RFP)
A30: TOTAL PROJECTED OPERATING COST | E30: =SUM(E27,E29) -> 0
A31: By submission of this bid, the bidder certifies that, in the event the bidder receives an award under this solicitation, the bidder shall operate in accordance with all applicable program laws and regulations. This contract shall be in effect for one year and may be renewed by mutual agreement for four additional one-year periods.
A33: FSMC Representative Signature | E33: Date
A35: NOTE: The Food Service Management Company must use this bid sheet when submitting its bid.

Sheet 15-Bid Sheet without adv pmt
A1: BID SHEET FSMC Cost Reimbursable Contract WITHOUT ADVANCE PAYMENT
A3: This bid is being offered by:
B4: Name of Food Service Management Company
A5: This bid is being offered to:
B6: Name of School Sponsor
A7: Projected Meals/Meal Equivalents Per Year: | C7: =SUM('12-Projected Revenue'!L35) -> 0 | D7: (do not alter, cell will auto-fill upon MDE review)
A9: Sponsor is contracting for the expenses indicated as Bid Items below | D9: Bid Items (Sponsor completes) | E9: Projected Operating Cost WITHOUT Advance Payment (Bidder completes)
A10: Labor - On-Site FSMC Management Employees
A11: Fringe Benefits - On-Site FSMC Management Employees
A12: Labor - FSMC Hourly Employees
A13: Fringe Benefits - FSMC Hourly Employees
A14: Food Cost for SNP, CACFP, and SFSP Meals (including commodities delivery charge) (net of VDA/rebates)
A15: Non-Food Cost for SNP, CACFP, and SFSP (supplies and other materials) | G15: Bidder will use the correct column to indicate if fees will be billed over a 10-month period, 12-month period, or by cost per meal/meal equivalent. Do not indicate costs in all 3 columns for each fee.
A16: Food Cost for FFVP (as defined in RFP)
A17: Non-Food Cost for FFVP (supplies and other materials) (as defined in RFP)
A18: Contracted Services (not utilities or FSMC administrative costs) | G18: School Year 2026-2027 Rates [will match the current rates on the SY 27-28 Renewal Rate Agreement Form (if renewed)]
A19: Transportation/Vehicle Cost
A20: Utilities (assigned to Food Service Fund) | G20: COST PER MONTH | J20: or | K20: COST PER MEAL / MEAL EQUIVALENT
A21: Other (as defined on Projected Costs tab) | G21: Monthly Fee (10 months) | H21: or | I21: Monthly Fee (12 months)
A22: FSMC Administrative Fee | D22: X | F22: FSMC Administrative Fee | H22: or | J22: or
A23: FSMC Management Fee | D23: X | F23: FSMC Management Fee | H23: or | J23: or
A24: Subtotal (Bid Items Only) | E24: =SUM(E10:E23) -> 0
A25: Bid Price Per Meal (subtotal divided by projected meals/meal equivalents) | E25: =E24/C7 -> #DIV/0!
A26: Additional Food Service Markup if applicable (refer to RFP)
A27: TOTAL PROJECTED OPERATING COST | E27: =SUM(E24,E26) -> 0
A28: By submission of this bid, the bidder certifies that, in the event the bidder receives an award under this solicitation, the bidder shall operate in accordance with all applicable program laws and regulations. This contract shall be in effect for one year and may be renewed by mutual agreement for four additional one-year periods.
A30: FSMC Representative Signature | E30: Date
A32: NOTE: The Food Service Management Company must use this bid sheet when submitting its bid.
